Workbook

Sheet Inputs
A1: To Save: File --> Make a Copy | Thanks, liftvault.com
A2: Also available on the Boostcamp app
A3: Candito 6 Week Strength Program | K3: Options
K4: Weight | L4: Upper Back #1 (Horizontal pull) | M4: Shoulders | N4: Upper Back #2 (vertical pull)
A5: Complete the fields in blue, and excel will automatically formulate your workouts, each week is printable. | K5: kg | L5: Dumbbell Row | M5: Seated Dumbbell OHP | N5: Weighted Pull-up
K6: lb | L6: Barbell Row | M6: Standing Dumbbell OHP | N6: Weighted Chin-up
A7: What date do you want to start the Program? | L7: Machine Row | M7: Military Press | N7: Lat Pulldown
A8: Date | B8: 45978 | M8: Lateral Dumbell Raise
A10: Do you track your weights in kilograms or pounds?
A11: Weights in | B11: kg
A13: What are your 1RM's for the following lifts?
A14: Bench Press | B14: 84.6 | C14: =B11 -> kg
A15: Squat | B15: 103.6 | C15: =B11 -> kg
A16: Deadlift | B16: 150 | C16: =B11 -> kg
A18: Choose Your Preferred Accessory Exercises
A19: Upper Back Exercise #1 (horizontal pull) | B19: Barbell Row
A20: Shoulder Exercise | B20: Military Press
A21: Upper Back Exercise #2 (vertical pull) | B21: Weighted Pull-up
A23: Additional Information
A24: MR = Max Reps
A25: MR10 = Max Reps but no more than 10.
A26: Deadlift Variation = Stiff Legged DL, Snatch Grip DL, Deficit DL, or Pause DL.
A27: If you ever fail a required rep, reduce your max by 2.5%.

Sheet Week 1 ✅
A1: Week 1 - Muscular Conditioning (W/ Moderate Difficulty)
A3: =Inputs!B8 -> 45978 | B3: ✅ (did only 5 instead of 6 on the last two sets of front squats)
C4: Set 1 | E4: Set 2 | G4: Set 3 | I4: Set 4
A5: Squat | B5: Warm Up | C5: =IF((Inputs!B11="kg"),MROUND((Inputs!B15*0.8),2.5),MROUND((Inputs!B15*0.8),5)) -> 82.5 | D5: x6 | E5: =C5 -> 82.5 | F5: x6 | G5: =E5 -> 82.5 | H5: x6 - did only 5 | I5: =G5 -> 82.5 | J5: x6 - did 5
A6: Deadlift | B6: Warm Up | C6: =IF((Inputs!B11="kg"),MROUND((Inputs!B16*0.8),2.5),MROUND((Inputs!B16*0.8),5)) -> 120 | D6: x6 | E6: =C6 -> 120 | F6: x6 | H6: x6 (didn
A7: Optional Exercise 1 | B7: Warm Up
A8: Optional Exercise 2 | B8: Warm Up
A10: =Inputs!B8+1 -> 45979 | B10: ✅
C11: Set 1 | E11: Set 2 | G11: Set 3 | I11: Set 4
A12: Bench Press | B12: Warm Up | C12: =IF((Inputs!B11="kg"),MROUND((Inputs!B14*0.5),2.5),MROUND((Inputs!B14*0.5),5)) -> 42.5 | D12: x10 | E12: =IF((Inputs!B11="kg"),MROUND((Inputs!B14*0.675),2.5),MROUND((Inputs!B14*0.675),5)) -> 57.5 | F12: x10 | G12: =IF((Inputs!B11="kg"),MROUND((Inputs!B14*0.75),2.5),MROUND((Inputs!B14*0.75),5)) -> 62.5 | H12: x8 | I12: =IF((Inputs!B11="kg"),MROUND((Inputs!B14*0.775),2.5),MROUND((Inputs!B14*0.775),5)) -> 65 | J12: x6
A13: =Inputs!B19 -> Barbell Row | B13: Warm Up | C13: 30 | D13: x10 | E13: 40 | F13: x10 | G13: 45 | H13: x8 | I13: 50 | J13: x6
A14: =Inputs!B20 -> Military Press | B14: Warm Up | C14: 20 | D14: x12 | E14: 30 | F14: x12 | G14: 32.5 | H14: x10 | I14: 35 | J14: x8
A15: =Inputs!B21 -> Weighted Pull-up | B15: Warm Up | C15: -65 | D15: x12 | E15: -60 | F15: x12 | G15: -55 | H15: x10 | I15: -50 | J15: x8
A16: Optional Exercise 1 | B16: Warm Up | D16: x8-12 | F16: x8-12 | H16: x8-12 | J16: x8-12
A17: Optional Exercise 2 | B17: Warm Up | D17: x8-12 | F17: x8-12 | H17: x8-12 | J17: x8-12
A19: =Inputs!B8+3 -> 45981 | B19: ✅
C20: Set 1 | E20: Set 2 | G20: Set 3 | I20: Set 4
A21: Bench Press | B21: Warm Up | C21: =IF((Inputs!B11="kg"),MROUND((Inputs!B14*0.5),2.5),MROUND((Inputs!B14*0.5),5)) -> 42.5 | D21: x10 | E21: =IF((Inputs!B11="kg"),MROUND((Inputs!B14*0.675),2.5),MROUND((Inputs!B14*0.675),5)) -> 57.5 | F21: x10 | G21: =IF((Inputs!B11="kg"),MROUND((Inputs!B14*0.75),2.5),MROUND((Inputs!B14*0.75),5)) -> 62.5 | H21: x8 | I21: =IF((Inputs!B11="kg"),MROUND((Inputs!B14*0.775),2.5),MROUND((Inputs!B14*0.775),5)) -> 65 | J21: x6
A22: =Inputs!B19 -> Barbell Row | B22: Warm Up | C22: 40 | D22: x10 | E22: 45 | F22: x10 | G22: 50 | H22: x8 | I22: 55 | J22: x6
A23: =Inputs!B20 -> Military Press | B23: Warm Up | C23: 25 | D23: x12 | E23: 30 | F23: x12 | G23: 32.5 | H23: x10 | I23: 35 | J23: x8 did only 6 because I FORGOT
A24: Normal pull-ups (was supposed to be weighted/assisted pull ups, but machine was busy) | B24: Warm Up | C24: BW | D24: x5 | E24: BW | F24: x5 | G24: BW | H24: x5 | I24: BW | J24: x5 | K24: Did normal pull ups here: 5 reps, 5 reps, 5 reps, 5 reps
A25: Optional Exercise 1 | B25: Warm Up | D25: x8-12 | F25: x8-12 | H25: x8-12 | J25: x8-12
A26: Optional Exercise 2 | B26: Warm Up | D26: x8-12 | F26: x8-12 | H26: x8-12 | J26: x8-12
A28: =Inputs!B8+4 -> 45982 | B28: 🟡 reduced reps
C29: Set 1 | E29: Set 2 | G29: Set 3 | I29: Set 4
A30: Squat | B30: Warm Up | C30: =IF((Inputs!B36="kg"),MROUND((Inputs!B15*0.7),2.5),MROUND((Inputs!B15*0.7),5)) -> 75 | D30: x8 | E30: =C30 -> 75 | F30: x8 - did only 6 | G30: =E30 -> 75 | H30: x8 | I30: =G30 -> 75 | J30: x8 - did 4, then +4
A31: Deadlift | B31: Warm Up | C31: =IF((Inputs!B36="kg"),MROUND((Inputs!B16*0.7),2.5),MROUND((Inputs!B16*0.7),5)) -> 105 | D31: x8 - did 6 | E31: =C31 -> 105 | F31: x8 - did 6
A32: Optional Exercise 1 | B32: Warm Up
A33: Optional Exercise 2 | B33: Warm Up
A35: =Inputs!B8+5 -> 45983 | B35: ✅
C36: Set 1 | E36: Set 2 | G36: Set 3 | I36: Set 4
A37: Bench Press | B37: Warm Up | C37: =IF((Inputs!B11="kg"),MROUND((Inputs!B14*0.8),2.5),MROUND((Inputs!B14*0.8),5)) -> 67.5 | D37: xMR - did 10
A38: =Inputs!B19 -> Barbell Row | B38: Warm Up | C38: 40 | D38: x10 | E38: 45 | F38: x10 | G38: 50 | H38: x8 | I38: 55 | J38: x6
A39: =Inputs!B20 -> Military Press | B39: Warm Up | C39: 25 | D39: x12 | E39: 30 | F39: x12 | G39: 32.5 | H39: x10 | I39: 35 | J39: x8
A40: =Inputs!B21 -> Weighted Pull-up | B40: Warm Up | C40: -60 | D40: x12 | E40: -55 | F40: x12 | G40: -50 | H40: x10 | I40: -45 | J40: x8
A41: Optional Exercise 1 | B41: Warm Up | D41: x8-12 | F41: x8-12 | H41: x8-12 | J41: x8-12
A42: Optional Exercise 2 | B42: Warm Up | D42: x8-12 | F42: x8-12 | H42: x8-12 | J42: x8-12

Sheet Week 2 ✅
A1: Week 2 - Muscular Conditioning/Hypertrophy (W/ Higher Difficulty)
A3: =Inputs!B8+7 -> 45985 | B3: ✅
C4: Set 1 | E4: Set 2 | G4: Set 3 | I4: Set 4
A5: Squat | B5: Warm Up | C5: =IF((Inputs!B11="kg"),MROUND((Inputs!B15*0.8),2.5),MROUND((Inputs!B15*0.8),5)) -> 82.5 | D5: xMR10 - did 8 | K5: 8 reps
A6: Extra Volume Squats - Add 5 lbs or 2.5 kg if using kg plates, then perform 5 sets x 3 reps each set with 60 seconds rest between sets. | K6: DONE!
A7: Note - If you were not able to complete a minimum of 8 reps on the MR10 set, reduce max entered by 2.5% moving forward.
A8: Still complete the 5 sets of 3 reps regardless even if you do perform less than 8 reps on the MR10 set.
A9: Deadlift Variation | B9: Warm Up | C9: 80 | D9: x8 | E9: 80 | F9: x8 | G9: 80 | H9: x8 | K9: First one normal grip, next ones inverse grip
A10: Optional Exercise 1 | B10: Warm Up
A11: Optional Exercise 2 | B11: Warm Up
A13: =Inputs!B8+8 -> 45986 | B13: ✅
C14: Set 1 | E14: Set 2 | G14: Set 3 | I14: Set 4
A15: Bench Press | B15: Warm Up | C15: =IF((Inputs!B11="kg"),MROUND((Inputs!B14*0.725),2.5),MROUND((Inputs!B14*0.725),5)) -> 62.5 | D15: x10 | E15: =IF((Inputs!B11="kg"),MROUND((Inputs!B14*0.775),2.5),MROUND((Inputs!B14*0.775),5)) -> 65 | F15: x8 | G15: =IF((Inputs!B11="kg"),(MROUND((Inputs!B14*0.8),2.5)+2.5),(MROUND((Inputs!B14*0.8),5)+5)) -> 70 | H15: x6-8 - did 8
A16: MACHINE ROW (replacement) | B16: Warm Up | C16: 55 | D16: x10 | E16: 60 | F16: x8 | G16: 65 | H16: x8 | K16: Gym full replaced by machine row!
A17: =Inputs!B20 -> Military Press | B17: Warm Up | C17: 30 | D17: x10 | E17: 35 | F17: x8 | G17: 40 | H17: x6
A18: =Inputs!B21 -> Weighted Pull-up | B18: Warm Up | C18: -50 | D18: x10 | E18: -45 | F18: x8 | G18: -40 | H18: x6
A19: Optional Exercise 1 | B19: Warm Up | D19: x8-12 | F19: x8-12 | H19: x8-12 | J19: x8-12
A20: Optional Exercise 2 | B20: Warm Up | D20: x8-12 | F20: x8-12 | H20: x8-12 | J20: x8-12
A22: =Inputs!B8+10 -> 45988 | B22: ✅
C23: Set 1 | E23: Set 2 | G23: Set 3 | I23: Set 4
A24: Squat | B24: Warm Up | C24: =IF((Inputs!B11="kg"),(MROUND((Inputs!B15*0.8),2.5)+2.5),(MROUND((Inputs!B15*0.8),5)+5)) -> 85 | D24: xMR10 - did 8
A25: Back Off Squats - Reduce weight by 10 lbs or 5 kg if using kg plates. Then proceed with the following:
A26: If you were able to complete 10 reps on the MR10 set, perform 10 sets of 3 reps per set, with 60 seconds rest between sets.
A27: If you completed 8-9 reps on the MR10 set, perform 8 sets of 3 reps per set, with 60 seconds rest between sets. | K27: 8 so far
A28: If you completed 7 reps on the MR 10 set, perform 5 sets of 3 reps per set, with 60 seconds rest between sets.
A29: If you completed less than 7 reps, skip back off sets entirely and reduce your entered 1 rep max by at least 2.5% for following weeks.
A30: Deadlift Variation | B30: Warm Up | C30: 70 | D30: x8 | E30: 80 | F30: x8 | G30: 80 | H30: x8
A31: Optional Exercise 1 | B31: Warm Up
A32: Optional Exercise 2 | B32: Warm Up
A34: =Inputs!B8+11 -> 45989 | B34: ✅
C35: Set 1 | E35: Set 2 | G35: Set 3 | I35: Set 4
A36: Bench Press | B36: Warm Up | C36: =IF((Inputs!B11="kg"),MROUND((Inputs!B14*0.725),2.5),MROUND((Inputs!B14*0.725),5)) -> 62.5 | D36: x10 | E36: =IF((Inputs!B11="kg"),MROUND((Inputs!B14*0.775),2.5),MROUND((Inputs!B14*0.775),5)) -> 65 | F36: x8 | G36: =IF((Inputs!B11="kg"),(MROUND((Inputs!B14*0.8),2.5)+2.5),(MROUND((Inputs!B14*0.8),5)+5)) -> 70 | H36: x6-8 - did 8
A37: =Inputs!B19 -> Barbell Row | B37: Warm Up | C37: 50 | D37: x10 | E37: 60 | F37: x8 | G37: 60 | H37: x8
A38: =Inputs!B20 -> Military Press | B38: Warm Up | C38: 30 | D38: x10 | E38: 37.5 | F38: x8 | G38: 42.5 | H38: x6
A39: =Inputs!B21 -> Weighted Pull-up | B39: Warm Up | C39: -45 | D39: x10 | E39: -40 | F39: x8 | G39: -25 (but effectively zero, I was faster than the thing, and -30 = 10kg up) | H39: x6
A40: Optional Exercise 1 | B40: Warm Up | D40: x8-12 | F40: x8-12 | H40: x8-12 | J40: x8-12
A41: Optional Exercise 2 | B41: Warm Up | D41: x8-12 | F41: x8-12 | H41: x8-12 | J41: x8-12
A43: =A34+2 -> 45991 | B43: Did it on saturday! | C43: ✅
C44: Set 1 | E44: Set 2 | G44: Set 3 | I44: Set 4
A45: Bench Press | B45: Warm Up | C45: =IF((Inputs!B11="kg"),(MROUND((Inputs!B14*0.8),2.5)-2.5),(MROUND((Inputs!B14*0.8),5)-5)) -> 65 | D45: xMR - did 13
...

Sheet Week 3 ✅
A1: Week 3 - Linear Max OT Phase
A3: =Inputs!B8+14 -> 45992 | B3: ✅
C4: Set 1 | E4: Set 2 | G4: Set 3 | I4: Set 4
A5: Squat | B5: Warm Up | C5: =IF((Inputs!B11="kg"),(MROUND((Inputs!B15*0.85),2.5)+2.5),(MROUND((Inputs!B15*0.85),5)+5)) -> 90 | D5: x4-6 - did 6 | E5: =IF((Inputs!B11="kg"),(MROUND((Inputs!B15*0.85),2.5)+2.5),(MROUND((Inputs!B15*0.85),5)+5)) -> 90 | F5: x4-6 - did 5 | G5: =IF((Inputs!B11="kg"),(MROUND((Inputs!B15*0.85),2.5)+2.5),(MROUND((Inputs!B15*0.85),5)+5)) -> 90 | H5: x4-6 - did 6
A6: Deadlift | B6: Warm Up | C6: =IF((Inputs!B11="kg"),MROUND((Inputs!B16*0.875),2.5),MROUND((Inputs!B16*0.875),5)) -> 132.5 | D6: x3-6 - did 5 | E6: =IF((Inputs!B11="kg"),MROUND((Inputs!B16*0.875),2.5),MROUND((Inputs!B16*0.875),5)) -> 132.5 | F6: x3-6 - did 4
A7: No Accessory Lifts
A9: =A3+2 -> 45994 | B9: ✅
C10: Set 1 | E10: Set 2 | G10: Set 3 | I10: Set 4
A11: Bench Press | B11: Warm Up | C11: =IF((Inputs!B11="kg"),MROUND((Inputs!B14*0.85),2.5),MROUND((Inputs!B14*0.85),5)) -> 72.5 | D11: x4-6 - did 6 | E11: =IF((Inputs!B11="kg"),MROUND((Inputs!B14*0.85),2.5),MROUND((Inputs!B14*0.85),5)) -> 72.5 | F11: x4-6 - did 6 | G11: =IF((Inputs!B11="kg"),MROUND((Inputs!B14*0.85),2.5),MROUND((Inputs!B14*0.85),5)) -> 72.5 | H11: x4-6
A12: =Inputs!B19 -> Barbell Row | B12: Warm Up | C12: 70 | D12: x6 | E12: 70 | F12: x6 | G12: 70 | H12: x6 | K12: Aim for 70kg slow
A13: =Inputs!B20 -> Military Press | B13: Warm Up | C13: 47.5 | D13: x6 | E13: 47.5 | F13: x6 | G13: 47.5 | H13: x6 - did 4, then tried again and got 0, then tried again and got the last 2 | K13: Aim for 47.5
A14: =Inputs!B21 -> Weighted Pull-up | B14: Warm Up | C14: 0kg | D14: x6 | E14: 0kg | F14: x6 | G14: 0kg | H14: x6 | K14: Aim for 3x6x0kg, if too easy learn how to add some weight
A15: No Optional Exercises
A17: =A9+2 -> 45996 | B17: ✅
C18: Set 1 | E18: Set 2 | G18: Set 3 | I18: Set 4
A19: Squat | B19: Warm Up | C19: =IF((Inputs!B11="kg"),(MROUND(((Inputs!B15*0.85)+2.5),2.5)+2.5),(MROUND(((Inputs!B15*0.85)+5),5)+5)) -> 92.5 | D19: x4-6 - did 4, then 2 after a pause
A20: Deadlift Variation | B20: Warm Up | C20: 75 | D20: x8
A21: No Accessory Lifts
A23: =A9+3 -> 45997 | B23: ✅
C24: Set 1 | E24: Set 2 | G24: Set 3 | I24: Set 4
A25: Bench Press | B25: Warm Up | C25: =IF((Inputs!B11="kg"),(C11+2.5),(C11+5)) -> 75 | D25: x4-6 - did 6 | E25: =IF((Inputs!B11="kg"),(E11+2.5),(E11+5)) -> 75 | F25: x4-6 - did 6 I think | G25: =IF((Inputs!B11="kg"),(G11+2.5),(G11+5)) -> 75 | H25: x4-6 - did 6 I think
A26: =Inputs!B19 -> Barbell Row | B26: Warm Up | C26: 70 | D26: x6 | E26: 70 | F26: x6 | G26: 70 | H26: x6
A27: =Inputs!B20 -> Military Press | B27: Warm Up | C27: 50 | D27: x6 | E27: 50 | F27: x6 - did 4 | G27: 50 | H27: x6 - did 4 | K27: Did 2 reps of 45kg
A28: =Inputs!B21 -> Weighted Pull-up | B28: Warm Up | C28: 0 | D28: x6 | E28: 0 | F28: x6 | G28: 0 | H28: x6
A29: No Optional Exercises

Sheet Week 4 ✅
A1: Week 4 - Heavy Weight Acclimation
A3: =Inputs!B8+21 -> 45999 | B3: ✅
C4: Set 1 | E4: Set 2 | G4: Set 3 | I4: Set 4
A5: Squat | B5: Warm Up | C5: =IF((Inputs!B11="kg"),(MROUND((Inputs!B15*0.9),2.5)-2.5),(MROUND((Inputs!B15*0.9),5)-5)) -> 90 | D5: x3 | E5: =IF((Inputs!B11="kg"),MROUND((Inputs!B15*0.9),2.5),MROUND((Inputs!B15*0.9),5)) -> 92.5 | F5: x3 | G5: =IF((Inputs!B11="kg"),(MROUND((Inputs!B15*0.9),2.5)+2.5),(MROUND((Inputs!B15*0.9),5)+5)) -> 95 | H5: x3 | K5: DONE
A6: Deadlift Variation | B6: Warm Up | C6: 80 | D6: x6 | E6: 90 | F6: x6
A7: Optional Exercise 1 | B7: Warm Up
A8: Optional Exercise 2 | B8: Warm Up
A10: =A3+1 -> 46000 | B10: ✅
C11: Set 1 | E11: Set 2 | G11: Set 3 | I11: Set 4
A12: Bench Press | B12: Warm Up | C12: =IF((Inputs!B11="kg"),MROUND(((Inputs!B14*0.875)-5),2.5),MROUND(((Inputs!B14*0.875)-5),5)) -> 70 | D12: x3 | E12: =IF((Inputs!B11="kg"),MROUND(((Inputs!B14*0.9)-5),2.5),MROUND(((Inputs!B14*0.9)-5),5)) -> 70 | F12: x3 | G12: =IF((Inputs!B11="kg"),MROUND((Inputs!B14*0.9),2.5),MROUND((Inputs!B14*0.9),5)) -> 75 | H12: x3 | K12: Doing it paused
A13: =Inputs!B19 -> Barbell Row | B13: Warm Up | C13: 50 | D13: x10 | E13: 60 | F13: x10 | G13: 70 | H13: x8 | I13: 72.5 | J13: x6
A14: =Inputs!B20 -> Military Press | B14: Warm Up | C14: 35 | D14: x12 | E14: 40 | F14: x12 - did 11+1 | G14: 42.5 | H14: x10 - did 6 | I14: 42.5 | J14: x8 - did 6
A15: =Inputs!B21 -> Weighted Pull-up | B15: Warm Up | C15: -40 | D15: x12 | E15: -40 | F15: x12 - did 10 | G15: -40 | H15: x10 - did 8 | I15: -45 | J15: x8
A16: Optional Exercise 1 | B16: Warm Up | D16: x8-12 | F16: x8-12 | H16: x8-12 | J16: x8-12
A17: Optional Exercise 2 | B17: Warm Up | D17: x8-12 | F17: x8-12 | H17: x8-12 | J17: x8-12
A19: =A10+2 -> 46002 | B19: Doing it the day after since I missed it on thursday | C19: ✅
C20: Set 1 | E20: Set 2 | G20: Set 3 | I20: Set 4
A21: Squat | B21: Warm Up | C21: =IF((Inputs!B11="kg"),(MROUND((Inputs!B15*0.9),2.5)+2.5),(MROUND((Inputs!B15*0.9),5)+5)) -> 95 | D21: x3 | E21: =IF((Inputs!B11="kg"),MROUND((Inputs!B15*0.95),2.5),MROUND((Inputs!B15*0.95),5)) -> 97.5 | F21: x1-2
A22: Deadlift | B22: Warm Up | C22: =IF((Inputs!B11="kg"),(MROUND((Inputs!B16*0.9),2.5)+2.5),(MROUND((Inputs!B16*0.9),5)+5)) -> 137.5 | D22: x3 | E22: =IF((Inputs!B11="kg"),MROUND((Inputs!B16*0.95),2.5),MROUND((Inputs!B16*0.95),5)) -> 142.5 | F22: x1-2
A23: Optional Exercise 1 | B23: Warm Up
A24: Optional Exercise 2 | B24: Warm Up
A26: =A19+1 -> 46003
C27: Set 1 | E27: Set 2 | G27: Set 3 | I27: Set 4
A28: Bench Press | B28: Warm Up | C28: =IF((Inputs!B11="kg"),MROUND((Inputs!B14*0.875),2.5),MROUND((Inputs!B14*0.875),5)) -> 75 | D28: x3 | E28: =IF((Inputs!B11="kg"),MROUND((Inputs!B14*0.9),2.5),MROUND((Inputs!B14*0.9),5)) -> 75 | F28: x2-4 | G28: =IF((Inputs!B11="kg"),MROUND((Inputs!B14*0.95),2.5),MROUND((Inputs!B14*0.95),5)) -> 80 | H28: x1-2 | K28: Did 3, 4, and then 2x80kg
A29: =Inputs!B19 -> Barbell Row | B29: Warm Up | C29: 60 | D29: x10 | E29: 60 | F29: x10 | G29: 62.5 | H29: x8 | I29: 67.5 | J29: x6
A30: =Inputs!B20 -> Military Press | B30: Warm Up | C30: 35 | D30: x12 | E30: 37.5 | F30: x12 - did 10 | G30: 37.5 | H30: x10 - did 8 | I30: 37.5 | J30: x8 - did 7
A31: =Inputs!B21 -> Weighted Pull-up | B31: Warm Up | C31: -45 | D31: x12 | E31: -45 | F31: x12 | G31: -50 | H31: x10 - did 8 | I31: -55 | J31: x8
A32: Optional Exercise 1 | B32: Warm Up | D32: x8-12 | F32: x8-12 | H32: x8-12 | J32: x8-12
A33: Optional Exercise 2 | B33: Warm Up | D33: x8-12 | F33: x8-12 | H33: x8-12 | J33: x8-12

Sheet Week 5 ✅
A1: Week 5 - High Intensity Strength
A3: =Inputs!B8+28 -> 46006 | B3: ✅
C4: Set 1 | E4: Set 2 | G4: Set 3 | I4: Set 4
A5: Squat | B5: Warm Up | C5: =IF((Inputs!B11="kg"),MROUND((Inputs!B15*0.975),2.5),MROUND((Inputs!B15*0.975),5)) -> 100 | D5: x1-4 | K5: Did 4
A6: Deadlift | B6: Warm Up | C6: =IF((Inputs!B11="kg"),MROUND((Inputs!B16*0.675),2.5),MROUND((Inputs!B16*0.675),5)) -> 102.5 | D6: x4 | E6: =IF((Inputs!B11="kg"),MROUND((Inputs!B16*0.7),2.5),MROUND((Inputs!B16*0.7),5)) -> 105 | F6: x4 | G6: =IF((Inputs!B11="kg"),MROUND((Inputs!B16*0.725),2.5),MROUND((Inputs!B16*0.725),5)) -> 110 | H6: x2
A7: Optional Lower Body | B7: Warm Up
A8: Optional Lower Body | B8: Warm Up
A10: =A3+2 -> 46008 | B10: ✅
C11: Set 1 | E11: Set 2 | G11: Set 3 | I11: Set 4
A12: Bench Press | B12: Warm Up | C12: =IF((Inputs!B11="kg"),MROUND((Inputs!B14*0.975),2.5),MROUND((Inputs!B14*0.975),5)) -> 82.5 | D12: x1-4 | K12: Did 4
A13: =Inputs!B19 -> Barbell Row | B13: Warm Up | C13: 60 | D13: x8 | E13: 72.5 | F13: x6 | G13: 72.5 | H13: x6
A14: =Inputs!B20 -> Military Press | B14: Warm Up | C14: 35 | D14: x8 | E14: 40 | F14: x6 | G14: 45 | H14: x6
A15: =Inputs!B21 -> Weighted Pull-up | B15: Warm Up | C15: -35 | D15: x8 | E15: 0 | F15: x6 | G15: 0 | H15: x6
A16: Optional Exercise 1 | B16: Warm Up | D16: x8-12 | F16: x8-12 | H16: x8-12
A17: Optional Exercise 2 | B17: Warm Up | D17: x8-12 | F17: x8-12 | H17: x8-12
A19: =A10+2 -> 46010 | B19: ✅
C20: Set 1 | E20: Set 2 | G20: Set 3 | I20: Set 4
A21: Deadlift | B21: Warm Up | C21: =IF((Inputs!B11="kg"),MROUND((Inputs!B16*0.975),2.5),MROUND((Inputs!B16*0.975),5)) -> 147.5 | D21: x1-4 | K21: Did 4
A22: Optional Lower Body | B22: Warm Up
A23: Optional Lower Body | B23: Warm Up

Sheet Week 6
A1: For Week 6 You Have 3 Options
A2: 1. Skip Week 6. Just use projected one rep max from last week's 1-4 rep set. Start next cycle.
A3: 2. Use projected max for next cycle, but take a deload week (repeat week 1 but skip last upper workout).
A4: 3. Take this 6th week to actually find your 1 rep max. Then either deload or start new cycle.
A6: Determining Projected Max
A7: Take what you lifted in week 5, and multiply by 1.03 if you completed 2 reps, 1.06 if 3 reps, and 1.09 if 4 reps.
A9: Enter your new 1RM's below to see your progress!
B10: Old 1RM | C10: New 1RM | D10: Increase
A11: Bench Press | B11: =Inputs!B14 -> 84.6 | C11: 90 | D11: =C11-B11 -> 5.4
A12: Squat | B12: =Inputs!B15 -> 103.6 | C12: 109.1 | D12: =C12-B12 -> 5.5
A13: Deadlift | B13: =Inputs!B16 -> 150 | C13: 160.9 | D13: =C13-B13 -> 10.9
A15: NOTE: decided to go with option #1, SKIP
